<?xml version="1.0" ?>
<!-- =================================================================================== -->
<!-- |    This document was autogenerated by xacro from antrobot.xacro                 | -->
<!-- |    EDITING THIS FILE BY HAND IS NOT RECOMMENDED                                 | -->
<!-- =================================================================================== -->
<robot name="antrobot">
  <!-- TODO: Colisions need to be updated to a simplified version -->
  <!-- TODO: Inertial can be aproximated with cilinders if the sim is slow -->
  <material name="silver">
    <color rgba="0.700 0.700 0.700 1.000"/>
  </material>
  <material name="red">
    <color rgba="0.902 0.196 0.157 1.000"/>
  </material>
  <material name="yellow">
    <color rgba="1 0.816 0.129 1.000"/>
  </material>
  <material name="blue">
    <color rgba="0.251 0.424 0.969 1.000"/>
  </material>
  <material name="dark_grey">
    <color rgba="0.341 0.361 0.431 1.000"/>
  </material>
  <material name="grey">
    <color rgba="0.576 0.592 0.639 1.000"/>
  </material>
  <material name="light_grey">
    <color rgba="0.788 0.812 0.878 1.000"/>
  </material>
  <transmission name="wheel_left_joint_tran">
    <type>transmission_interface/SimpleTransmission</type>
    <joint name="wheel_left_joint">
      <hardwareInterface>hardware_interface/EffortJointInterface</hardwareInterface>
    </joint>
    <actuator name="wheel_left_joint_actr">
      <hardwareInterface>hardware_interface/EffortJointInterface</hardwareInterface>
      <mechanicalReduction>1</mechanicalReduction>
    </actuator>
  </transmission>
  <transmission name="wheel_right_joint_tran">
    <type>transmission_interface/SimpleTransmission</type>
    <joint name="wheel_right_joint">
      <hardwareInterface>hardware_interface/EffortJointInterface</hardwareInterface>
    </joint>
    <actuator name="wheel_right_joint_actr">
      <hardwareInterface>hardware_interface/EffortJointInterface</hardwareInterface>
      <mechanicalReduction>1</mechanicalReduction>
    </actuator>
  </transmission>
  <!-- 
Attention: The approach has changed for the new Gazebo 
      Transform the URDF in actual SDF with the required plugins.
      You need to develop full on packages according to the ignition gazebo template,
      where fortress is compatible with humble.

      This file is left here for visualization purposes as a strating point,
      but otherwise usable for simulations or digital twins.
-->
  <!-- TODO: Fix this for gazebo ignition -->
  <!-- <gazebo>
  <plugin name="control" filename="libgazebo_ros_control.so"/>
</gazebo> -->
  <!-- <gazebo>
  <plugin name="ign_ros2_control" filename="libign_ros2_control.so">
    <ros>
      <namespace>/</namespace>
      <remapping>joint_states:=/joint_states</remapping>
    </ros>
    <robotNamespace>/</robotNamespace>
    <robotSimType>ign_ros2_control/DefaultRobotHWSim</robotSimType>
  </plugin>
</gazebo> -->
  <gazebo reference="base_link">
    <material>Gazebo/Silver</material>
    <mu1>0.2</mu1>
    <mu2>0.2</mu2>
    <self_collide>true</self_collide>
    <gravity>true</gravity>
  </gazebo>
  <gazebo reference="wheel_left_link">
    <material>Gazebo/Blue</material>
    <mu1>0.2</mu1>
    <mu2>0.2</mu2>
    <self_collide>true</self_collide>
  </gazebo>
  <gazebo reference="wheel_right_link">
    <material>Gazebo/Blue</material>
    <mu1>0.2</mu1>
    <mu2>0.2</mu2>
    <self_collide>true</self_collide>
  </gazebo>
  <gazebo reference="rplidar_link">
    <material>Gazebo/Red</material>
    <mu1>0.2</mu1>
    <mu2>0.2</mu2>
    <self_collide>true</self_collide>
  </gazebo>
  <gazebo reference="rpicam_link">
    <material>Gazebo/Yellow</material>
    <mu1>0.2</mu1>
    <mu2>0.2</mu2>
    <self_collide>true</self_collide>
  </gazebo>
  <gazebo reference="realsense_link">
    <material>Gazebo/Yellow</material>
    <mu1>0.2</mu1>
    <mu2>0.2</mu2>
    <self_collide>true</self_collide>
  </gazebo>
  <!-- This must be checked, we don't want to fix the robot to the origin -->
  <link name="robot_origin">
    <visual>
      <origin rpy="0 0 0" xyz="0 0 0"/>
      <geometry>
        <box size="0.0001 0.0001 0.0001"/>
      </geometry>
    </visual>
    <collision>
      <origin rpy="0 0 0" xyz="0 0 0"/>
      <geometry>
        <box size="0.0001 0.0001 0.0001"/>
      </geometry>
    </collision>
  </link>
  <joint name="base_joint" type="fixed">
    <origin rpy="0 0 0" xyz="0 0 0.034999999999999996"/>
    <parent link="robot_origin"/>
    <child link="base_link"/>
  </joint>
  <!-- <link name="robot_origin" />

<joint name="robot_origin" type="fixed">
  <parent link="base_footprint" />
  <child link="base_link" />
</joint> -->
  <link name="base_link">
    <inertial>
      <origin rpy="0 0 0" xyz="-0.015797588649762044 0.0004259128735104659 0.06300813597085958"/>
      <mass value="1.5945437281135275"/>
      <inertia ixx="0.008584" ixy="-6e-06" ixz="-0.0002" iyy="0.010164" iyz="-3.3e-05" izz="0.010169"/>
    </inertial>
    <visual>
      <origin rpy="0 0 0" xyz="0 0 0"/>
      <geometry>
        <mesh filename="file:///home/dan/workspace/ros2_ws/install/antrobot_description/share/antrobot_description/meshes/base_link.stl" scale="0.001 0.001 0.001"/>
      </geometry>
      <material name="light_grey"/>
    </visual>
    <collision>
      <origin rpy="0 0 0" xyz="0 0 0"/>
      <geometry>
        <mesh filename="file:///home/dan/workspace/ros2_ws/install/antrobot_description/share/antrobot_description/meshes/base_link.stl" scale="0.001 0.001 0.001"/>
      </geometry>
    </collision>
  </link>
  <link name="base_footprint"/>
  <link name="wheel_left_link">
    <inertial>
      <origin rpy="0 0 0" xyz="-1.2728583304935648e-06 -0.0023063066184155906 6.00040961839729e-08"/>
      <mass value="0.010031169181516577"/>
      <inertia ixx="3e-06" ixy="-0.0" ixz="0.0" iyy="6e-06" iyz="-0.0" izz="3e-06"/>
    </inertial>
    <visual>
      <origin rpy="0 0 0" xyz="-0.029613 -0.1095 0.005"/>
      <geometry>
        <mesh filename="file:///home/dan/workspace/ros2_ws/install/antrobot_description/share/antrobot_description/meshes/wheel_left_link.stl" scale="0.001 0.001 0.001"/>
      </geometry>
      <material name="blue"/>
    </visual>
    <collision>
      <origin rpy="0 0 0" xyz="-0.029613 -0.1095 0.005"/>
      <geometry>
        <mesh filename="file:///home/dan/workspace/ros2_ws/install/antrobot_description/share/antrobot_description/meshes/wheel_left_link.stl" scale="0.001 0.001 0.001"/>
      </geometry>
    </collision>
  </link>
  <link name="wheel_right_link">
    <inertial>
      <origin rpy="0 0 0" xyz="1.4357516585211672e-06 0.002306307129465418 6.000408169209298e-08"/>
      <mass value="0.010031169181516577"/>
      <inertia ixx="3e-06" ixy="-0.0" ixz="-0.0" iyy="6e-06" iyz="0.0" izz="3e-06"/>
    </inertial>
    <visual>
      <origin rpy="0 0 0" xyz="-0.029613 0.1095 0.005"/>
      <geometry>
        <mesh filename="file:///home/dan/workspace/ros2_ws/install/antrobot_description/share/antrobot_description/meshes/wheel_right_link.stl" scale="0.001 0.001 0.001"/>
      </geometry>
      <material name="blue"/>
    </visual>
    <collision>
      <origin rpy="0 0 0" xyz="-0.029613 -0.1095 0.005"/>
      <geometry>
        <mesh filename="file:///home/dan/workspace/ros2_ws/install/antrobot_description/share/antrobot_description/meshes/wheel_right_link.stl" scale="0.001 0.001 0.001"/>
      </geometry>
    </collision>
  </link>
  <link name="rplidar_link">
    <inertial>
      <origin rpy="0 0 0" xyz="0.0030931959904156093 -0.0003163045555262638 0.021005003394948152"/>
      <mass value="0.044595018191553856"/>
      <inertia ixx="2.5e-05" ixy="0.0" ixz="-1e-06" iyy="2.5e-05" iyz="0.0" izz="3.6e-05"/>
    </inertial>
    <visual>
      <origin rpy="0 0 0" xyz="-0.0 -0.0 -0.186"/>
      <geometry>
        <mesh filename="file:///home/dan/workspace/ros2_ws/install/antrobot_description/share/antrobot_description/meshes/rplidar_link.stl" scale="0.001 0.001 0.001"/>
      </geometry>
      <material name="red"/>
    </visual>
    <collision>
      <origin rpy="0 0 0" xyz="-0.0 -0.0 -0.186"/>
      <geometry>
        <mesh filename="file:///home/dan/workspace/ros2_ws/install/antrobot_description/share/antrobot_description/meshes/rplidar_link.stl" scale="0.001 0.001 0.001"/>
      </geometry>
    </collision>
  </link>
  <link name="rpicam_link">
    <inertial>
      <origin rpy="0 0 0" xyz="-0.006587669853958977 5.666710231481823e-05 1.5965148283683672e-05"/>
      <mass value="0.0016269917920669669"/>
      <inertia ixx="0.0" ixy="0.0" ixz="0.0" iyy="0.0" iyz="0.0" izz="0.0"/>
    </inertial>
    <visual>
      <origin rpy="0 0 0" xyz="-0.126235 -8.8e-05 -0.031943"/>
      <geometry>
        <mesh filename="file:///home/dan/workspace/ros2_ws/install/antrobot_description/share/antrobot_description/meshes/rpicam_link.stl" scale="0.001 0.001 0.001"/>
      </geometry>
      <material name="yellow"/>
    </visual>
    <collision>
      <origin rpy="0 0 0" xyz="-0.126235 -8.8e-05 -0.031943"/>
      <geometry>
        <mesh filename="file:///home/dan/workspace/ros2_ws/install/antrobot_description/share/antrobot_description/meshes/rpicam_link.stl" scale="0.001 0.001 0.001"/>
      </geometry>
    </collision>
  </link>
  <link name="realsense_link">
    <inertial>
      <origin rpy="0 0 0" xyz="-0.012605676757880976 0.001112839462886813 0.0006324082805583275"/>
      <mass value="0.04843109891123876"/>
      <inertia ixx="2.9e-05" ixy="0.0" ixz="0.0" iyy="4e-06" iyz="-0.0" izz="3e-05"/>
    </inertial>
    <visual>
      <origin rpy="0 0 0" xyz="-0.111521 -0.00012 -0.132217"/>
      <geometry>
        <mesh filename="file:///home/dan/workspace/ros2_ws/install/antrobot_description/share/antrobot_description/meshes/realsense_link.stl" scale="0.001 0.001 0.001"/>
      </geometry>
      <material name="yellow"/>
    </visual>
    <collision>
      <origin rpy="0 0 0" xyz="-0.111521 -0.00012 -0.132217"/>
      <geometry>
        <mesh filename="file:///home/dan/workspace/ros2_ws/install/antrobot_description/share/antrobot_description/meshes/realsense_link.stl" scale="0.001 0.001 0.001"/>
      </geometry>
    </collision>
  </link>
  <joint name="wheel_left_joint" type="continuous">
    <origin rpy="0 0 0" xyz="0.029613 0.1095 -0.005"/>
    <parent link="base_link"/>
    <child link="wheel_left_link"/>
    <axis xyz="-0.0 1.0 -0.0"/>
  </joint>
  <joint name="wheel_right_joint" type="continuous">
    <origin rpy="0 0 0" xyz="0.029613 -0.1095 -0.005"/>
    <parent link="base_link"/>
    <child link="wheel_right_link"/>
    <axis xyz="0.0 -1.0 0.0"/>
  </joint>
  <joint name="rplidar_joint" type="fixed">
    <origin rpy="0 0 0" xyz="0.0 0.0 0.186"/>
    <parent link="base_link"/>
    <child link="rplidar_link"/>
  </joint>
  <joint name="rpicam_joint" type="fixed">
    <origin rpy="0 0.0523599 0" xyz="0.126235 8.8e-05 0.031943"/>
    <parent link="base_link"/>
    <child link="rpicam_link"/>
  </joint>
  <joint name="realsense_joint" type="fixed">
    <origin rpy="0 0.0523599 0" xyz="0.111521 0.00012 0.132217"/>
    <parent link="base_link"/>
    <child link="realsense_link"/>
  </joint>
  <joint name="base_footprint_joint" type="fixed">
    <origin rpy="0 0 0" xyz="0 0 -0.034999999999999996"/>
    <parent link="base_link"/>
    <child link="base_footprint"/>
  </joint>
</robot>
